Workbook

Sheet Summary
B1: Healthcare Data Analysis & Insights
B2: Module End Assignment 1-EXCEL
B4: Sheet guide
B5: Cleaning Summary | C5: "?" counts per column, fill values (year average, mode for smoker / tiers), Heart Issues & smoker consistency check, and editable parameters (as-of date, BMI / HbA1C cut-offs).
B6: Customer Names | C6: Raw names + Title, First Name, Last Name split by formulas.
B7: Medical Examinations | C7: Raw columns (grey) + cleaned columns, numeric surgeries, Weight Status, Diabetes Status (blue).
B8: Hospitalisation Details | C8: Raw columns (grey) + cleaned year/month/tiers/State ID, Date of Birth (DD-MMM-YYYY) and Age as of 8-Jun-2023 (blue). Charges formatted in $.
B9: Healthcare | C9: The three tables combined with VLOOKUP on Customer ID (17 required columns).
B10: Analysis / Chart Data | C10: Pivot-style summary tables and the helper columns behind the charts.
B11: Dashboard | C11: All charts, KPI tiles and the two slicer-style filters (Weight Status, Diabetes Status).
B13: Key findings (all 2,335 patients, no filters)
B14: Cancer vs smoking | C14: Cancer history is 17.2% among smokers (84 of 488) and 16.6% among non-smokers (307 of 1847): no meaningful difference in this dataset.
B15: Transplants | C15: Patients with a transplant (144) average 1.12 major surgeries each vs 0.65 without; total surgeries are 162 vs 1417 because far fewer patients have had transplants. Average HbA1C is lower with a transplant (5.19 vs 6.67).
B16: Charges by weight & diabetes | C16: Average charges generally rise with weight status and are highest for Obesity + Diabetes ($19,348); lowest for Underweight + Prediabetes ($5,648). Diabetes has the highest average charges in every weight group, while Prediabetes is not consistently above Normal (e.g. Underweight, Overweight).
B17: Hospital tier & state | C17: Tier 1 hospitals have the highest average charges in every state that has tier 1 patients except R1014 (about $30k overall vs $12k for tier 2 and $9k for tier 3). Most patients sit in R1011, R1012 and R1013; several small states have few or no tier 1 patients, so their averages rest on very few records.
B18: Age correlations | C18: Age vs HbA1C r = 0.46 (moderate positive); age vs charges r = 0.30 (moderate positive); age vs BMI r = 0.05 (negligible).
B20: Assumptions & data-quality notes
B21: Year fill | C21: Average of the numeric years = 1982.84, rounded to 1983.
B22: Mode fills | C22: smoker → No; Hospital tier → tier - 2; City tier → tier - 2. Missing State ID → "Unknown".
B23: Unmatched rows | C23: Hospitalisation Details has 8 rows that cannot be linked to a customer: 6 with Customer ID "?" and 2 orphan IDs (id2444, id3444) not found in the other tables. They are excluded from Healthcare (2,335 customers).
B24: First Name | C24: Everything after the title is kept, so a middle initial stays (e.g. "Matthew D").
B25: Date of Birth / Age | C25: Built from year, month, date (cleaned). Age = completed years as of 8-Jun-2023 using DATEDIF.
B26: Averages vs totals | C26: Charts compare AVERAGE charges because group sizes differ widely; counts are shown in the Analysis sheet.
B27: Filters | C27: Slicer-style dropdowns on the Dashboard drive SUMIFS/AVERAGEIFS and the scatter helper columns. Scatter points outside the filter return NA() on Chart Data on purpose, so Excel leaves them off the charts.
B29: Optional: add real PivotTables & Slicers in Excel (2 minutes)
B30: PivotTable | C30: Click inside Healthcare → Insert → PivotTable → New worksheet. Drag fields as in the Analysis tables (e.g. Weight Status to Rows, Diabetes Status to Columns, charges to Values as Average).
B31: Slicers | C31: Select a PivotTable → PivotTable Analyze → Insert Slicer → tick Weight Status and Diabetes Status → Report Connections → tick all PivotTables.

Sheet Cleaning Summary
A1: Data Cleaning Summary & Transformation Parameters
A4: 1. Missing values marked "?" (per column)
A5: Table | B5: Column | C5: Count of "?"
A6: Medical Examinations | B6: Customer ID | C6: =SUMPRODUCT(--(TRIM('Medical Examinations'!$A$2:$A$2336)="?")) -> 0
A7: Medical Examinations | B7: BMI | C7: =SUMPRODUCT(--(TRIM('Medical Examinations'!$B$2:$B$2336)="?")) -> 0
A8: Medical Examinations | B8: HBA1C | C8: =SUMPRODUCT(--(TRIM('Medical Examinations'!$C$2:$C$2336)="?")) -> 0
A9: Medical Examinations | B9: Heart Issues | C9: =SUMPRODUCT(--(TRIM('Medical Examinations'!$D$2:$D$2336)="?")) -> 0
A10: Medical Examinations | B10: Any Transplants | C10: =SUMPRODUCT(--(TRIM('Medical Examinations'!$E$2:$E$2336)="?")) -> 0
A11: Medical Examinations | B11: Cancer history | C11: =SUMPRODUCT(--(TRIM('Medical Examinations'!$F$2:$F$2336)="?")) -> 0
A12: Medical Examinations | B12: NumberOfMajorSurgeries | C12: =SUMPRODUCT(--(TRIM('Medical Examinations'!$G$2:$G$2336)="?")) -> 0
A13: Medical Examinations | B13: smoker | C13: =SUMPRODUCT(--(TRIM('Medical Examinations'!$H$2:$H$2336)="?")) -> 2
A14: Hospitalisation Details | B14: Customer ID | C14: =SUMPRODUCT(--(TRIM('Hospitalisation Details'!$A$2:$A$2344)="?")) -> 6
A15: Hospitalisation Details | B15: year | C15: =SUMPRODUCT(--(TRIM('Hospitalisation Details'!$B$2:$B$2344)="?")) -> 2
A16: Hospitalisation Details | B16: month | C16: =SUMPRODUCT(--(TRIM('Hospitalisation Details'!$C$2:$C$2344)="?")) -> 3
A17: Hospitalisation Details | B17: date | C17: =SUMPRODUCT(--(TRIM('Hospitalisation Details'!$D$2:$D$2344)="?")) -> 0
A18: Hospitalisation Details | B18: children | C18: =SUMPRODUCT(--(TRIM('Hospitalisation Details'!$E$2:$E$2344)="?")) -> 0
A19: Hospitalisation Details | B19: charges | C19: =SUMPRODUCT(--(TRIM('Hospitalisation Details'!$F$2:$F$2344)="?")) -> 0
A20: Hospitalisation Details | B20: Hospital tier | C20: =SUMPRODUCT(--(TRIM('Hospitalisation Details'!$G$2:$G$2344)="?")) -> 1
A21: Hospitalisation Details | B21: City tier | C21: =SUMPRODUCT(--(TRIM('Hospitalisation Details'!$H$2:$H$2344)="?")) -> 1
A22: Hospitalisation Details | B22: State ID | C22: =SUMPRODUCT(--(TRIM('Hospitalisation Details'!$I$2:$I$2344)="?")) -> 2
A23: Total | C23: =SUM(C6:C22) -> 17
A25: 2. Fill values used for missing data
A26: Item | B26: Value used | C26: How it is decided
A27: month | B27: Sep | C27: Given in the brief (Sep is also the most frequent month)
A28: year | B28: =ROUND(AVERAGE('Hospitalisation Details'!$B$2:$B$2344),0) -> 1983 | C28: Average of all numeric years (text "?" ignored), rounded to nearest integer
A29: State ID | B29: Unknown | C29: Missing State ID labelled "Unknown" so the rows stay in the analysis
A31: Most frequent value (mode) for smoker, Hospital tier and City tier
A32: Column | B32: Category | C32: Count (excl. "?")
A33: smoker | B33: No | C33: =COUNTIF('Medical Examinations'!$H$2:$H$2336,B33) -> 1845
A34: smoker | B34: Yes | C34: =COUNTIF('Medical Examinations'!$H$2:$H$2336,B34) -> 488
A35: Mode → smoker | B35: =INDEX(B33:B34,MATCH(MAX(C33:C34),C33:C34,0)) -> No | C35: ← value used to fill "?"
A37: Hospital tier | B37: tier - 1 | C37: =COUNTIF('Hospitalisation Details'!$G$2:$G$2344,B37) -> 309
A38: Hospital tier | B38: tier - 2 | C38: =COUNTIF('Hospitalisation Details'!$G$2:$G$2344,B38) -> 1339
A39: Hospital tier | B39: tier - 3 | C39: =COUNTIF('Hospitalisation Details'!$G$2:$G$2344,B39) -> 694
A40: Mode → Hospital tier | B40: =INDEX(B37:B39,MATCH(MAX(C37:C39),C37:C39,0)) -> tier - 2 | C40: ← value used to fill "?"
A42: City tier | B42: tier - 1 | C42: =COUNTIF('Hospitalisation Details'!$H$2:$H$2344,B42) -> 734
A43: City tier | B43: tier - 2 | C43: =COUNTIF('Hospitalisation Details'!$H$2:$H$2344,B43) -> 812
A44: City tier | B44: tier - 3 | C44: =COUNTIF('Hospitalisation Details'!$H$2:$H$2344,B44) -> 796
A45: Mode → City tier | B45: =INDEX(B42:B44,MATCH(MAX(C42:C44),C42:C44,0)) -> tier - 2 | C45: ← value used to fill "?"
A47: 3. Consistency check: Heart Issues and smoker (case-sensitive counts)
...

Sheet Customer Names
A1: Customer ID | B1: name | C1: Title | D1: First Name | E1: Last Name
A2: Id1 | B2: Hawks, Ms. Kelly | C2: =TRIM(MID(B2,FIND(",",B2)+1,FIND(".",B2,FIND(",",B2))-FIND(",",B2))) -> Ms. | D2: =TRIM(MID(B2,FIND(".",B2,FIND(",",B2))+1,100)) -> Kelly | E2: =TRIM(LEFT(B2,FIND(",",B2)-1)) -> Hawks
A3: Id2 | B3: Lehner, Mr. Matthew D | C3: =TRIM(MID(B3,FIND(",",B3)+1,FIND(".",B3,FIND(",",B3))-FIND(",",B3))) -> Mr. | D3: =TRIM(MID(B3,FIND(".",B3,FIND(",",B3))+1,100)) -> Matthew D | E3: =TRIM(LEFT(B3,FIND(",",B3)-1)) -> Lehner
A4: Id3 | B4: Lu, Mr. Phil | C4: =TRIM(MID(B4,FIND(",",B4)+1,FIND(".",B4,FIND(",",B4))-FIND(",",B4))) -> Mr. | D4: =TRIM(MID(B4,FIND(".",B4,FIND(",",B4))+1,100)) -> Phil | E4: =TRIM(LEFT(B4,FIND(",",B4)-1)) -> Lu
A5: Id4 | B5: Osborne, Ms. Kelsey | C5: =TRIM(MID(B5,FIND(",",B5)+1,FIND(".",B5,FIND(",",B5))-FIND(",",B5))) -> Ms. | D5: =TRIM(MID(B5,FIND(".",B5,FIND(",",B5))+1,100)) -> Kelsey | E5: =TRIM(LEFT(B5,FIND(",",B5)-1)) -> Osborne
A6: Id5 | B6: Kadala, Ms. Kristyn | C6: =TRIM(MID(B6,FIND(",",B6)+1,FIND(".",B6,FIND(",",B6))-FIND(",",B6))) -> Ms. | D6: =TRIM(MID(B6,FIND(".",B6,FIND(",",B6))+1,100)) -> Kristyn | E6: =TRIM(LEFT(B6,FIND(",",B6)-1)) -> Kadala
A7: Id6 | B7: Baker, Mr. Russell B. | C7: =TRIM(MID(B7,FIND(",",B7)+1,FIND(".",B7,FIND(",",B7))-FIND(",",B7))) -> Mr. | D7: =TRIM(MID(B7,FIND(".",B7,FIND(",",B7))+1,100)) -> Russell B. | E7: =TRIM(LEFT(B7,FIND(",",B7)-1)) -> Baker
A8: Id7 | B8: Macpherson, Mr. Scott | C8: =TRIM(MID(B8,FIND(",",B8)+1,FIND(".",B8,FIND(",",B8))-FIND(",",B8))) -> Mr. | D8: =TRIM(MID(B8,FIND(".",B8,FIND(",",B8))+1,100)) -> Scott | E8: =TRIM(LEFT(B8,FIND(",",B8)-1)) -> Macpherson
A9: Id8 | B9: Hallman, Mr. Stephen | C9: =TRIM(MID(B9,FIND(",",B9)+1,FIND(".",B9,FIND(",",B9))-FIND(",",B9))) -> Mr. | D9: =TRIM(MID(B9,FIND(".",B9,FIND(",",B9))+1,100)) -> Stephen | E9: =TRIM(LEFT(B9,FIND(",",B9)-1)) -> Hallman
A10: Id9 | B10: Moran, Mr. Patrick R. | C10: =TRIM(MID(B10,FIND(",",B10)+1,FIND(".",B10,FIND(",",B10))-FIND(",",B10))) -> Mr. | D10: =TRIM(MID(B10,FIND(".",B10,FIND(",",B10))+1,100)) -> Patrick R. | E10: =TRIM(LEFT(B10,FIND(",",B10)-1)) -> Moran
A11: Id10 | B11: Benner, Ms. Brooke N. | C11: =TRIM(MID(B11,FIND(",",B11)+1,FIND(".",B11,FIND(",",B11))-FIND(",",B11))) -> Ms. | D11: =TRIM(MID(B11,FIND(".",B11,FIND(",",B11))+1,100)) -> Brooke N. | E11: =TRIM(LEFT(B11,FIND(",",B11)-1)) -> Benner
A12: Id11 | B12: Fierro Vargas, Ms. Paola Andrea | C12: =TRIM(MID(B12,FIND(",",B12)+1,FIND(".",B12,FIND(",",B12))-FIND(",",B12))) -> Ms. | D12: =TRIM(MID(B12,FIND(".",B12,FIND(",",B12))+1,100)) -> Paola Andrea | E12: =TRIM(LEFT(B12,FIND(",",B12)-1)) -> Fierro Vargas
A13: Id12 | B13: Franz, Mr. David | C13: =TRIM(MID(B13,FIND(",",B13)+1,FIND(".",B13,FIND(",",B13))-FIND(",",B13))) -> Mr. | D13: =TRIM(MID(B13,FIND(".",B13,FIND(",",B13))+1,100)) -> David | E13: =TRIM(LEFT(B13,FIND(",",B13)-1)) -> Franz
... A2336: Id2335 | B2336: German, Mr. Aaron K | C2336: =TRIM(MID(B2336,FIND(",",B2336)+1,FIND(".",B2336,FIND(",",B2336))-FIND(",",B2336))) -> Mr. | D2336: =TRIM(MID(B2336,FIND(".",B2336,FIND(",",B2336))+1,100)) -> Aaron K | E2336: =TRIM(LEFT(B2336,FIND(",",B2336)-1)) -> German

Sheet Medical Examinations
A1: Customer ID | B1: BMI | C1: HBA1C | D1: Heart Issues | E1: Any Transplants | F1: Cancer history | G1: NumberOfMajorSurgeries | H1: smoker | I1: Heart Issues (clean) | J1: Any Transplants (clean) | K1: Cancer history (clean) | L1: smoker (clean) | M1: NumberOfMajorSurgeries (numeric) | N1: Weight Status | O1: Diabetes Status
A2: Id1 | B2: 47.41 | C2: 7.47 | D2: No | E2: No | F2: No | G2: No major surgery | H2: yes | I2: =IF(LOWER(TRIM(D2))="yes","Yes","No") -> No | J2: =IF(LOWER(TRIM(E2))="yes","Yes","No") -> No | K2: =IF(LOWER(TRIM(F2))="yes","Yes","No") -> No | L2: =IF(TRIM(H2)="?",'Cleaning Summary'!$B$35,IF(LOWER(TRIM(H2))="yes","Yes","No")) -> Yes | M2: =IF(ISNUMBER(G2),G2,IF(LOWER(TRIM(G2))="no major surgery",0,"CHECK")) -> 0 | N2: =IF(B2<'Cleaning Summary'!$B$63,"Underweight",IF(B2<'Cleaning Summary'!$B$64,"Normal Weight",IF(B2<'Cleaning Summary'!$B$65,"Overweight","Obesity"))) -> Obesity | O2: =IF(C2<'Cleaning Summary'!$B$66,"Normal",IF(C2<'Cleaning Summary'!$B$67,"Prediabetes","Diabetes")) -> Diabetes
A3: Id2 | B3: 30.36 | C3: 5.77 | D3: No | E3: No | F3: No | G3: No major surgery | H3: yes | I3: =IF(LOWER(TRIM(D3))="yes","Yes","No") -> No | J3: =IF(LOWER(TRIM(E3))="yes","Yes","No") -> No | K3: =IF(LOWER(TRIM(F3))="yes","Yes","No") -> No | L3: =IF(TRIM(H3)="?",'Cleaning Summary'!$B$35,IF(LOWER(TRIM(H3))="yes","Yes","No")) -> Yes | M3: =IF(ISNUMBER(G3),G3,IF(LOWER(TRIM(G3))="no major surgery",0,"CHECK")) -> 0 | N3: =IF(B3<'Cleaning Summary'!$B$63,"Underweight",IF(B3<'Cleaning Summary'!$B$64,"Normal Weight",IF(B3<'Cleaning Summary'!$B$65,"Overweight","Obesity"))) -> Obesity | O3: =IF(C3<'Cleaning Summary'!$B$66,"Normal",IF(C3<'Cleaning Summary'!$B$67,"Prediabetes","Diabetes")) -> Prediabetes
A4: Id3 | B4: 34.485 | C4: 11.87 | D4: yes | E4: No | F4: No | G4: 2 | H4: yes | I4: =IF(LOWER(TRIM(D4))="yes","Yes","No") -> Yes | J4: =IF(LOWER(TRIM(E4))="yes","Yes","No") -> No | K4: =IF(LOWER(TRIM(F4))="yes","Yes","No") -> No | L4: =IF(TRIM(H4)="?",'Cleaning Summary'!$B$35,IF(LOWER(TRIM(H4))="yes","Yes","No")) -> Yes | M4: =IF(ISNUMBER(G4),G4,IF(LOWER(TRIM(G4))="no major surgery",0,"CHECK")) -> 2 | N4: =IF(B4<'Cleaning Summary'!$B$63,"Underweight",IF(B4<'Cleaning Summary'!$B$64,"Normal Weight",IF(B4<'Cleaning Summary'!$B$65,"Overweight","Obesity"))) -> Obesity | O4: =IF(C4<'Cleaning Summary'!$B$66,"Normal",IF(C4<'Cleaning Summary'!$B$67,"Prediabetes","Diabetes")) -> Diabetes
A5: Id4 | B5: 38.095 | C5: 6.05 | D5: No | E5: No | F5: No | G5: No major surgery | H5: yes | I5: =IF(LOWER(TRIM(D5))="yes","Yes","No") -> No | J5: =IF(LOWER(TRIM(E5))="yes","Yes","No") -> No | K5: =IF(LOWER(TRIM(F5))="yes","Yes","No") -> No | L5: =IF(TRIM(H5)="?",'Cleaning Summary'!$B$35,IF(LOWER(TRIM(H5))="yes","Yes","No")) -> Yes | M5: =IF(ISNUMBER(G5),G5,IF(LOWER(TRIM(G5))="no major surgery",0,"CHECK")) -> 0 | N5: =IF(B5<'Cleaning Summary'!$B$63,"Underweight",IF(B5<'Cleaning Summary'!$B$64,"Normal Weight",IF(B5<'Cleaning Summary'!$B$65,"Overweight","Obesity"))) -> Obesity | O5: =IF(C5<'Cleaning Summary'!$B$66,"Normal",IF(C5<'Cleaning Summary'!$B$67,"Prediabetes","Diabetes")) -> Prediabetes
A6: Id5 | B6: 35.53 | C6: 5.45 | D6: No | E6: No | F6: No | G6: No major surgery | H6: yes | I6: =IF(LOWER(TRIM(D6))="yes","Yes","No") -> No | J6: =IF(LOWER(TRIM(E6))="yes","Yes","No") -> No | K6: =IF(LOWER(TRIM(F6))="yes","Yes","No") -> No | L6: =IF(TRIM(H6)="?",'Cleaning Summary'!$B$35,IF(LOWER(TRIM(H6))="yes","Yes","No")) -> Yes | M6: =IF(ISNUMBER(G6),G6,IF(LOWER(TRIM(G6))="no major surgery",0,"CHECK")) -> 0 | N6: =IF(B6<'Cleaning Summary'!$B$63,"Underweight",IF(B6<'Cleaning Summary'!$B$64,"Normal Weight",IF(B6<'Cleaning Summary'!$B$65,"Overweight","Obesity"))) -> Obesity | O6: =IF(C6<'Cleaning Summary'!$B$66,"Normal",IF(C6<'Cleaning Summary'!$B$67,"Prediabetes","Diabetes")) -> Normal
A7: Id6 | B7: 32.8 | C7: 6.59 | D7: No | E7: No | F7: No | G7: No major surgery | H7: yes | I7: =IF(LOWER(TRIM(D7))="yes","Yes","No") -> No | J7: =IF(LOWER(TRIM(E7))="yes","Yes","No") -> No | K7: =IF(LOWER(TRIM(F7))="yes","Yes","No") -> No | L7: =IF(TRIM(H7)="?",'Cleaning Summary'!$B$35,IF(LOWER(TRIM(H7))="yes","Yes","No")) -> Yes | M7: =IF(ISNUMBER(G7),G7,IF(LOWER(TRIM(G7))="no major surgery",0,"CHECK")) -> 0 | N7: =IF(B7<'Cleaning Summary'!$B$63,"Underweight",IF(B7<'Cleaning Summary'!$B$64,"Normal Weight",IF(B7<'Cleaning Summary'!$B$65,"Overweight","Obesity"))) -> Obesity | O7: =IF(C7<'Cleaning Summary'!$B$66,"Normal",IF(C7<'Cleaning Summary'!$B$67,"Prediabetes","Diabetes")) -> Diabetes
A8: Id7 | B8: 36.4 | C8: 6.07 | D8: No | E8: No | F8: No | G8: No major surgery | H8: yes | I8: =IF(LOWER(TRIM(D8))="yes","Yes","No") -> No | J8: =IF(LOWER(TRIM(E8))="yes","Yes","No") -> No | K8: =IF(LOWER(TRIM(F8))="yes","Yes","No") -> No | L8: =IF(TRIM(H8)="?",'Cleaning Summary'!$B$35,IF(LOWER(TRIM(H8))="yes","Yes","No")) -> Yes | M8: =IF(ISNUMBER(G8),G8,IF(LOWER(TRIM(G8))="no major surgery",0,"CHECK")) -> 0 | N8: =IF(B8<'Cleaning Summary'!$B$63,"Underweight",IF(B8<'Cleaning Summary'!$B$64,"Normal Weight",IF(B8<'Cleaning Summary'!$B$65,"Overweight","Obesity"))) -> Obesity | O8: =IF(C8<'Cleaning Summary'!$B$66,"Normal",IF(C8<'Cleaning Summary'!$B$67,"Prediabetes","Diabetes")) -> Prediabetes
A9: Id8 | B9: 36.96 | C9: 7.93 | D9: No | E9: No | F9: No | G9: 3 | H9: yes | I9: =IF(LOWER(TRIM(D9))="yes","Yes","No") -> No | J9: =IF(LOWER(TRIM(E9))="yes","Yes","No") -> No | K9: =IF(LOWER(TRIM(F9))="yes","Yes","No") -> No | L9: =IF(TRIM(H9)="?",'Cleaning Summary'!$B$35,IF(LOWER(TRIM(H9))="yes","Yes","No")) -> Yes | M9: =IF(ISNUMBER(G9),G9,IF(LOWER(TRIM(G9))="no major surgery",0,"CHECK")) -> 3 | N9: =IF(B9<'Cleaning Summary'!$B$63,"Underweight",IF(B9<'Cleaning Summary'!$B$64,"Normal Weight",IF(B9<'Cleaning Summary'!$B$65,"Overweight","Obesity"))) -> Obesity | O9: =IF(C9<'Cleaning Summary'!$B$66,"Normal",IF(C9<'Cleaning Summary'!$B$67,"Prediabetes","Diabetes")) -> Diabetes
A10: Id9 | B10: 41.14 | C10: 9.58 | D10: yes | E10: No | F10: Yes | G10: 1 | H10: yes | I10: =IF(LOWER(TRIM(D10))="yes","Yes","No") -> Yes | J10: =IF(LOWER(TRIM(E10))="yes","Yes","No") -> No | K10: =IF(LOWER(TRIM(F10))="yes","Yes","No") -> Yes | L10: =IF(TRIM(H10)="?",'Cleaning Summary'!$B$35,IF(LOWER(TRIM(H10))="yes","Yes","No")) -> Yes | M10: =IF(ISNUMBER(G10),G10,IF(LOWER(TRIM(G10))="no major surgery",0,"CHECK")) -> 1 | N10: =IF(B10<'Cleaning Summary'!$B$63,"Underweight",IF(B10<'Cleaning Summary'!$B$64,"Normal Weight",IF(B10<'Cleaning Summary'!$B$65,"Overweight","Obesity"))) -> Obesity | O10: =IF(C10<'Cleaning Summary'!$B$66,"Normal",IF(C10<'Cleaning Summary'!$B$67,"Prediabetes","Diabetes")) -> Diabetes
A11: Id10 | B11: 38.06 | C11: 10.79 | D11: No | E11: No | F11: No | G11: No major surgery | H11: yes | I11: =IF(LOWER(TRIM(D11))="yes","Yes","No") -> No | J11: =IF(LOWER(TRIM(E11))="yes","Yes","No") -> No | K11: =IF(LOWER(TRIM(F11))="yes","Yes","No") -> No | L11: =IF(TRIM(H11)="?",'Cleaning Summary'!$B$35,IF(LOWER(TRIM(H11))="yes","Yes","No")) -> Yes | M11: =IF(ISNUMBER(G11),G11,IF(LOWER(TRIM(G11))="no major surgery",0,"CHECK")) -> 0 | N11: =IF(B11<'Cleaning Summary'!$B$63,"Underweight",IF(B11<'Cleaning Summary'!$B$64,"Normal Weight",IF(B11<'Cleaning Summary'!$B$65,"Overweight","Obesity"))) -> Obesity | O11: =IF(C11<'Cleaning Summary'!$B$66,"Normal",IF(C11<'Cleaning Summary'!$B$67,"Prediabetes","Diabetes")) -> Diabetes
A12: Id11 | B12: 37.7 | C12: 5.96 | D12: yes | E12: No | F12: No | G12: 2 | H12: yes | I12: =IF(LOWER(TRIM(D12))="yes","Yes","No") -> Yes | J12: =IF(LOWER(TRIM(E12))="yes","Yes","No") -> No | K12: =IF(LOWER(TRIM(F12))="yes","Yes","No") -> No | L12: =IF(TRIM(H12)="?",'Cleaning Summary'!$B$35,IF(LOWER(TRIM(H12))="yes","Yes","No")) -> Yes | M12: =IF(ISNUMBER(G12),G12,IF(LOWER(TRIM(G12))="no major surgery",0,"CHECK")) -> 2 | N12: =IF(B12<'Cleaning Summary'!$B$63,"Underweight",IF(B12<'Cleaning Summary'!$B$64,"Normal Weight",IF(B12<'Cleaning Summary'!$B$65,"Overweight","Obesity"))) -> Obesity | O12: =IF(C12<'Cleaning Summary'!$B$66,"Normal",IF(C12<'Cleaning Summary'!$B$67,"Prediabetes","Diabetes")) -> Prediabetes
A13: Id12 | B13: 42.13 | C13: 11.9 | D13: No | E13: No | F13: No | G13: No major surgery | H13: yes | I13: =IF(LOWER(TRIM(D13))="yes","Yes","No") -> No | J13: =IF(LOWER(TRIM(E13))="yes","Yes","No") -> No | K13: =IF(LOWER(TRIM(F13))="yes","Yes","No") -> No | L13: =IF(TRIM(H13)="?",'Cleaning Summary'!$B$35,IF(LOWER(TRIM(H13))="yes","Yes","No")) -> Yes | M13: =IF(ISNUMBER(G13),G13,IF(LOWER(TRIM(G13))="no major surgery",0,"CHECK")) -> 0 | N13: =IF(B13<'Cleaning Summary'!$B$63,"Underweight",IF(B13<'Cleaning Summary'!$B$64,"Normal Weight",IF(B13<'Cleaning Summary'!$B$65,"Overweight","Obesity"))) -> Obesity | O13: =IF(C13<'Cleaning Summary'!$B$66,"Normal",IF(C13<'Cleaning Summary'!$B$67,"Prediabetes","Diabetes")) -> Diabetes
A14: Id13 | B14: 40.92 | C14: 8.41 | D14: No | E14: No | F14: No | G14: No major surgery | H14: yes | I14: =IF(LOWER(TRIM(D14))="yes","Yes","No") -> No | J14: =IF(LOWER(TRIM(E14))="yes","Yes","No") -> No | K14: =IF(LOWER(TRIM(F14))="yes","Yes","No") -> No | L14: =IF(TRIM(H14)="?",'Cleaning Summary'!$B$35,IF(LOWER(TRIM(H14))="yes","Yes","No")) -> Yes | M14: =IF(ISNUMBER(G14),G14,IF(LOWER(TRIM(G14))="no major surgery",0,"CHECK")) -> 0 | N14: =IF(B14<'Cleaning Summary'!$B$63,"Underweight",IF(B14<'Cleaning Summary'!$B$64,"Normal Weight",IF(B14<'Cleaning Summary'!$B$65,"Overweight","Obesity"))) -> Obesity | O14: =IF(C14<'Cleaning Summary'!$B$66,"Normal",IF(C14<'Cleaning Summary'!$B$67,"Prediabetes","Diabetes")) -> Diabetes
A15: Id14 | B15: 40.565 | C15: 7.02 | D15: No | E15: No | F15: No | G15: No major surgery | H15: yes | I15: =IF(LOWER(TRIM(D15))="yes","Yes","No") -> No | J15: =IF(LOWER(TRIM(E15))="yes","Yes","No") -> No | K15: =IF(LOWER(TRIM(F15))="yes","Yes","No") -> No | L15: =IF(TRIM(H15)="?",'Cleaning Summary'!$B$35,IF(LOWER(TRIM(H15))="yes","Yes","No")) -> Yes | M15: =IF(ISNUMBER(G15),G15,IF(LOWER(TRIM(G15))="no major surgery",0,"CHECK")) -> 0 | N15: =IF(B15<'Cleaning Summary'!$B$63,"Underweight",IF(B15<'Cleaning Summary'!$B$64,"Normal Weight",IF(B15<'Cleaning Summary'!$B$65,"Overweight","Obesity"))) -> Obesity | O15: =IF(C15<'Cleaning Summary'!$B$66,"Normal",IF(C15<'Cleaning Summary'!$B$67,"Prediabetes","Diabetes")) -> Diabetes
A16: Id15 | B16: 36.385 | C16: 7.59 | D16: yes | E16: No | F16: No | G16: 2 | H16: yes | I16: =IF(LOWER(TRIM(D16))="yes","Yes","No") -> Yes | J16: =IF(LOWER(TRIM(E16))="yes","Yes","No") -> No | K16: =IF(LOWER(TRIM(F16))="yes","Yes","No") -> No | L16: =IF(TRIM(H16)="?",'Cleaning Summary'!$B$35,IF(LOWER(TRIM(H16))="yes","Yes","No")) -> Yes | M16: =IF(ISNUMBER(G16),G16,IF(LOWER(TRIM(G16))="no major surgery",0,"CHECK")) -> 2 | N16: =IF(B16<'Cleaning Summary'!$B$63,"Underweight",IF(B16<'Cleaning Summary'!$B$64,"Normal Weight",IF(B16<'Cleaning Summary'!$B$65,"Overweight","Obesity"))) -> Obesity | O16: =IF(C16<'Cleaning Summary'!$B$66,"Normal",IF(C16<'Cleaning Summary'!$B$67,"Prediabetes","Diabetes")) -> Diabetes
A17: Id16 | B17: 39.9 | C17: 11.32 | D17: No | E17: No | F17: No | G17: No major surgery | H17: yes | I17: =IF(LOWER(TRIM(D17))="yes","Yes","No") -> No | J17: =IF(LOWER(TRIM(E17))="yes","Yes","No") -> No | K17: =IF(LOWER(TRIM(F17))="yes","Yes","No") -> No | L17: =IF(TRIM(H17)="?",'Cleaning Summary'!$B$35,IF(LOWER(TRIM(H17))="yes","Yes","No")) -> Yes | M17: =IF(ISNUMBER(G17),G17,IF(LOWER(TRIM(G17))="no major surgery",0,"CHECK")) -> 0 | N17: =IF(B17<'Cleaning Summary'!$B$63,"Underweight",IF(B17<'Cleaning Summary'!$B$64,"Normal Weight",IF(B17<'Cleaning Summary'!$B$65,"Overweight","Obesity"))) -> Obesity | O17: =IF(C17<'Cleaning Summary'!$B$66,"Normal",IF(C17<'Cleaning Summary'!$B$67,"Prediabetes","Diabetes")) -> Diabetes
A18: Id17 | B18: 33.8 | C18: 7.67 | D18: No | E18: No | F18: No | G18: 3 | H18: yes | I18: =IF(LOWER(TRIM(D18))="yes","Yes","No") -> No | J18: =IF(LOWER(TRIM(E18))="yes","Yes","No") -> No | K18: =IF(LOWER(TRIM(F18))="yes","Yes","No") -> No | L18: =IF(TRIM(H18)="?",'Cleaning Summary'!$B$35,IF(LOWER(TRIM(H18))="yes","Yes","No")) -> Yes | M18: =IF(ISNUMBER(G18),G18,IF(LOWER(TRIM(G18))="no major surgery",0,"CHECK")) -> 3 | N18: =IF(B18<'Cleaning Summary'!$B$63,"Underweight",IF(B18<'Cleaning Summary'!$B$64,"Normal Weight",IF(B18<'Cleaning Summary'!$B$65,"Overweight","Obesity"))) -> Obesity | O18: =IF(C18<'Cleaning Summary'!$B$66,"Normal",IF(C18<'Cleaning Summary'!$B$67,"Prediabetes","Diabetes")) -> Diabetes
A19: Id18 | B19: 36.765 | C19: 7.29 | D19: yes | E19: No | F19: Yes | G19: 1 | H19: yes | I19: =IF(LOWER(TRIM(D19))="yes","Yes","No") -> Yes | J19: =IF(LOWER(TRIM(E19))="yes","Yes","No") -> No | K19: =IF(LOWER(TRIM(F19))="yes","Yes","No") -> Yes | L19: =IF(TRIM(H19)="?",'Cleaning Summary'!$B$35,IF(LOWER(TRIM(H19))="yes","Yes","No")) -> Yes | M19: =IF(ISNUMBER(G19),G19,IF(LOWER(TRIM(G19))="no major surgery",0,"CHECK")) -> 1 | N19: =IF(B19<'Cleaning Summary'!$B$63,"Underweight",IF(B19<'Cleaning Summary'!$B$64,"Normal Weight",IF(B19<'Cleaning Summary'!$B$65,"Overweight","Obesity"))) -> Obesity | O19: =IF(C19<'Cleaning Summary'!$B$66,"Normal",IF(C19<'Cleaning Summary'!$B$67,"Prediabetes","Diabetes")) -> Diabetes
A20: Id19 | B20: 36.955 | C20: 4.72 | D20: yes | E20: No | F20: No | G20: 1 | H20: yes | I20: =IF(LOWER(TRIM(D20))="yes","Yes","No") -> Yes | J20: =IF(LOWER(TRIM(E20))="yes","Yes","No") -> No | K20: =IF(LOWER(TRIM(F20))="yes","Yes","No") -> No | L20: =IF(TRIM(H20)="?",'Cleaning Summary'!$B$35,IF(LOWER(TRIM(H20))="yes","Yes","No")) -> Yes | M20: =IF(ISNUMBER(G20),G20,IF(LOWER(TRIM(G20))="no major surgery",0,"CHECK")) -> 1 | N20: =IF(B20<'Cleaning Summary'!$B$63,"Underweight",IF(B20<'Cleaning Summary'!$B$64,"Normal Weight",IF(B20<'Cleaning Summary'!$B$65,"Overweight","Obesity"))) -> Obesity | O20: =IF(C20<'Cleaning Summary'!$B$66,"Normal",IF(C20<'Cleaning Summary'!$B$67,"Prediabetes","Diabetes")) -> Normal
A21: Id20 | B21: 42.9 | C21: 11.41 | D21: No | E21: No | F21: No | G21: No major surgery | H21: yes | I21: =IF(LOWER(TRIM(D21))="yes","Yes","No") -> No | J21: =IF(LOWER(TRIM(E21))="yes","Yes","No") -> No | K21: =IF(LOWER(TRIM(F21))="yes","Yes","No") -> No | L21: =IF(TRIM(H21)="?",'Cleaning Summary'!$B$35,IF(LOWER(TRIM(H21))="yes","Yes","No")) -> Yes | M21: =IF(ISNUMBER(G21),G21,IF(LOWER(TRIM(G21))="no major surgery",0,"CHECK")) -> 0 | N21: =IF(B21<'Cleaning Summary'!$B$63,"Underweight",IF(B21<'Cleaning Summary'!$B$64,"Normal Weight",IF(B21<'Cleaning Summary'!$B$65,"Overweight","Obesity"))) -> Obesity | O21: =IF(C21<'Cleaning Summary'!$B$66,"Normal",IF(C21<'Cleaning Summary'!$B$67,"Prediabetes","Diabetes")) -> Diabetes
A22: Id21 | B22: 36.3 | C22: 11.5 | D22: yes | E22: No | F22: No | G22: 2 | H22: yes | I22: =IF(LOWER(TRIM(D22))="yes","Yes","No") -> Yes | J22: =IF(LOWER(TRIM(E22))="yes","Yes","No") -> No | K22: =IF(LOWER(TRIM(F22))="yes","Yes","No") -> No | L22: =IF(TRIM(H22)="?",'Cleaning Summary'!$B$35,IF(LOWER(TRIM(H22))="yes","Yes","No")) -> Yes | M22: =IF(ISNUMBER(G22),G22,IF(LOWER(TRIM(G22))="no major surgery",0,"CHECK")) -> 2 | N22: =IF(B22<'Cleaning Summary'!$B$63,"Underweight",IF(B22<'Cleaning Summary'!$B$64,"Normal Weight",IF(B22<'Cleaning Summary'!$B$65,"Overweight","Obesity"))) -> Obesity | O22: =IF(C22<'Cleaning Summary'!$B$66,"Normal",IF(C22<'Cleaning Summary'!$B$67,"Prediabetes","Diabetes")) -> Diabetes
A23: Id22 | B23: 32.2 | C23: 6.22 | D23: yes | E23: No | F23: No | G23: 2 | H23: yes | I23: =IF(LOWER(TRIM(D23))="yes","Yes","No") -> Yes | J23: =IF(LOWER(TRIM(E23))="yes","Yes","No") -> No | K23: =IF(LOWER(TRIM(F23))="yes","Yes","No") -> No | L23: =IF(TRIM(H23)="?",'Cleaning Summary'!$B$35,IF(LOWER(TRIM(H23))="yes","Yes","No")) -> Yes | M23: =IF(ISNUMBER(G23),G23,IF(LOWER(TRIM(G23))="no major surgery",0,"CHECK")) -> 2 | N23: =IF(B23<'Cleaning Summary'!$B$63,"Underweight",IF(B23<'Cleaning Summary'!$B$64,"Normal Weight",IF(B23<'Cleaning Summary'!$B$65,"Overweight","Obesity"))) -> Obesity | O23: =IF(C23<'Cleaning Summary'!$B$66,"Normal",IF(C23<'Cleaning Summary'!$B$67,"Prediabetes","Diabetes")) -> Prediabetes
A24: Id23 | B24: 31.3 | C24: 11.38 | D24: No | E24: No | F24: No | G24: 3 | H24: yes | I24: =IF(LOWER(TRIM(D24))="yes","Yes","No") -> No | J24: =IF(LOWER(TRIM(E24))="yes","Yes","No") -> No | K24: =IF(LOWER(TRIM(F24))="yes","Yes","No") -> No | L24: =IF(TRIM(H24)="?",'Cleaning Summary'!$B$35,IF(LOWER(TRIM(H24))="yes","Yes","No")) -> Yes | M24: =IF(ISNUMBER(G24),G24,IF(LOWER(TRIM(G24))="no major surgery",0,"CHECK")) -> 3 | N24: =IF(B24<'Cleaning Summary'!$B$63,"Underweight",IF(B24<'Cleaning Summary'!$B$64,"Normal Weight",IF(B24<'Cleaning Summary'!$B$65,"Overweight","Obesity"))) -> Obesity | O24: =IF(C24<'Cleaning Summary'!$B$66,"Normal",IF(C24<'Cleaning Summary'!$B$67,"Prediabetes","Diabetes")) -> Diabetes
A25: Id24 | B25: 41.8 | C25: 7.89 | D25: yes | E25: No | F25: No | G25: 2 | H25: yes | I25: =IF(LOWER(TRIM(D25))="yes","Yes","No") -> Yes | J25: =IF(LOWER(TRIM(E25))="yes","Yes","No") -> No | K25: =IF(LOWER(TRIM(F25))="yes","Yes","No") -> No | L25: =IF(TRIM(H25)="?",'Cleaning Summary'!$B$35,IF(LOWER(TRIM(H25))="yes","Yes","No")) -> Yes | M25: =IF(ISNUMBER(G25),G25,IF(LOWER(TRIM(G25))="no major surgery",0,"CHECK")) -> 2 | N25: =IF(B25<'Cleaning Summary'!$B$63,"Underweight",IF(B25<'Cleaning Summary'!$B$64,"Normal Weight",IF(B25<'Cleaning Summary'!$B$65,"Overweight","Obesity"))) -> Obesity | O25: =IF(C25<'Cleaning Summary'!$B$66,"Normal",IF(C25<'Cleaning Summary'!$B$67,"Prediabetes","Diabetes")) -> Diabetes
A26: Id25 | B26: 35.09 | C26: 4.38 | D26: yes | E26: No | F26: No | G26: 2 | H26: yes | I26: =IF(LOWER(TRIM(D26))="yes","Yes","No") -> Yes | J26: =IF(LOWER(TRIM(E26))="yes","Yes","No") -> No | K26: =IF(LOWER(TRIM(F26))="yes","Yes","No") -> No | L26: =IF(TRIM(H26)="?",'Cleaning Summary'!$B$35,IF(LOWER(TRIM(H26))="yes","Yes","No")) -> Yes | M26: =IF(ISNUMBER(G26),G26,IF(LOWER(TRIM(G26))="no major surgery",0,"CHECK")) -> 2 | N26: =IF(B26<'Cleaning Summary'!$B$63,"Underweight",IF(B26<'Cleaning Summary'!$B$64,"Normal Weight",IF(B26<'Cleaning Summary'!$B$65,"Overweight","Obesity"))) -> Obesity | O26: =IF(C26<'Cleaning Summary'!$B$66,"Normal",IF(C26<'Cleaning Summary'!$B$67,"Prediabetes","Diabetes")) -> Normal
A27: Id26 | B27: 33.88 | C27: 7.01 | D27: No | E27: No | F27: No | G27: 3 | H27: yes | I27: =IF(LOWER(TRIM(D27))="yes","Yes","No") -> No | J27: =IF(LOWER(TRIM(E27))="yes","Yes","No") -> No | K27: =IF(LOWER(TRIM(F27))="yes","Yes","No") -> No | L27: =IF(TRIM(H27)="?",'Cleaning Summary'!$B$35,IF(LOWER(TRIM(H27))="yes","Yes","No")) -> Yes | M27: =IF(ISNUMBER(G27),G27,IF(LOWER(TRIM(G27))="no major surgery",0,"CHECK")) -> 3 | N27: =IF(B27<'Cleaning Summary'!$B$63,"Underweight",IF(B27<'Cleaning Summary'!$B$64,"Normal Weight",IF(B27<'Cleaning Summary'!$B$65,"Overweight","Obesity"))) -> Obesity | O27: =IF(C27<'Cleaning Summary'!$B$66,"Normal",IF(C27<'Cleaning Summary'!$B$67,"Prediabetes","Diabetes")) -> Diabetes
A28: Id27 | B28: 30.875 | C28: 11.88 | D28: No | E28: No | F28: No | G28: No major surgery | H28: yes | I28: =IF(LOWER(TRIM(D28))="yes","Yes","No") -> No | J28: =IF(LOWER(TRIM(E28))="yes","Yes","No") -> No | K28: =IF(LOWER(TRIM(F28))="yes","Yes","No") -> No | L28: =IF(TRIM(H28)="?",'Cleaning Summary'!$B$35,IF(LOWER(TRIM(H28))="yes","Yes","No")) -> Yes | M28: =IF(ISNUMBER(G28),G28,IF(LOWER(TRIM(G28))="no major surgery",0,"CHECK")) -> 0 | N28: =IF(B28<'Cleaning Summary'!$B$63,"Underweight",IF(B28<'Cleaning Summary'!$B$64,"Normal Weight",IF(B28<'Cleaning Summary'!$B$65,"Overweight","Obesity"))) -> Obesity | O28: =IF(C28<'Cleaning Summary'!$B$66,"Normal",IF(C28<'Cleaning Summary'!$B$67,"Prediabetes","Diabetes")) -> Diabetes
A29: Id28 | B29: 36.86 | C29: 5.19 | D29: yes | E29: No | F29: Yes | G29: 1 | H29: yes | I29: =IF(LOWER(TRIM(D29))="yes","Yes","No") -> Yes | J29: =IF(LOWER(TRIM(E29))="yes","Yes","No") -> No | K29: =IF(LOWER(TRIM(F29))="yes","Yes","No") -> Yes | L29: =IF(TRIM(H29)="?",'Cleaning Summary'!$B$35,IF(LOWER(TRIM(H29))="yes","Yes","No")) -> Yes | M29: =IF(ISNUMBER(G29),G29,IF(LOWER(TRIM(G29))="no major surgery",0,"CHECK")) -> 1 | N29: =IF(B29<'Cleaning Summary'!$B$63,"Underweight",IF(B29<'Cleaning Summary'!$B$64,"Normal Weight",IF(B29<'Cleaning Summary'!$B$65,"Overweight","Obesity"))) -> Obesity | O29: =IF(C29<'Cleaning Summary'!$B$66,"Normal",IF(C29<'Cleaning Summary'!$B$67,"Prediabetes","Diabetes")) -> Normal
A30: Id29 | B30: 35.86 | C30: 6.74 | D30: yes | E30: No | F30: No | G30: 2 | H30: yes | I30: =IF(LOWER(TRIM(D30))="yes","Yes","No") -> Yes | J30: =IF(LOWER(TRIM(E30))="yes","Yes","No") -> No | K30: =IF(LOWER(TRIM(F30))="yes","Yes","No") -> No | L30: =IF(TRIM(H30)="?",'Cleaning Summary'!$B$35,IF(LOWER(TRIM(H30))="yes","Yes","No")) -> Yes | M30: =IF(ISNUMBER(G30),G30,IF(LOWER(TRIM(G30))="no major surgery",0,"CHECK")) -> 2 | N30: =IF(B30<'Cleaning Summary'!$B$63,"Underweight",IF(B30<'Cleaning Summary'!$B$64,"Normal Weight",IF(B30<'Cleaning Summary'!$B$65,"Overweight","Obesity"))) -> Obesity | O30: =IF(C30<'Cleaning Summary'!$B$66,"Normal",IF(C30<'Cleaning Summary'!$B$67,"Prediabetes","Diabetes")) -> Diabetes
A31: Id30 | B31: 37.05 | C31: 8.44 | D31: No | E31: No | F31: No | G31: No major surgery | H31: yes | I31: =IF(LOWER(TRIM(D31))="yes","Yes","No") -> No | J31: =IF(LOWER(TRIM(E31))="yes","Yes","No") -> No | K31: =IF(LOWER(TRIM(F31))="yes","Yes","No") -> No | L31: =IF(TRIM(H31)="?",'Cleaning Summary'!$B$35,IF(LOWER(TRIM(H31))="yes","Yes","No")) -> Yes | M31: =IF(ISNUMBER(G31),G31,IF(LOWER(TRIM(G31))="no major surgery",0,"CHECK")) -> 0 | N31: =IF(B31<'Cleaning Summary'!$B$63,"Underweight",IF(B31<'Cleaning Summary'!$B$64,"Normal Weight",IF(B31<'Cleaning Summary'!$B$65,"Overweight","Obesity"))) -> Obesity | O31: =IF(C31<'Cleaning Summary'!$B$66,"Normal",IF(C31<'Cleaning Summary'!$B$67,"Prediabetes","Diabetes")) -> Diabetes
A32: Id31 | B32: 43.89 | C32: 8.71 | D32: No | E32: No | F32: No | G32: No major surgery | H32: yes | I32: =IF(LOWER(TRIM(D32))="yes","Yes","No") -> No | J32: =IF(LOWER(TRIM(E32))="yes","Yes","No") -> No | K32: =IF(LOWER(TRIM(F32))="yes","Yes","No") -> No | L32: =IF(TRIM(H32)="?",'Cleaning Summary'!$B$35,IF(LOWER(TRIM(H32))="yes","Yes","No")) -> Yes | M32: =IF(ISNUMBER(G32),G32,IF(LOWER(TRIM(G32))="no major surgery",0,"CHECK")) -> 0 | N32: =IF(B32<'Cleaning Summary'!$B$63,"Underweight",IF(B32<'Cleaning Summary'!$B$64,"Normal Weight",IF(B32<'Cleaning Summary'!$B$65,"Overweight","Obesity"))) -> Obesity | O32: =IF(C32<'Cleaning Summary'!$B$66,"Normal",IF(C32<'Cleaning Summary'!$B$67,"Prediabetes","Diabetes")) -> Diabetes
A33: Id32 | B33: 42.35 | C33: 5.08 | D33: yes | E33: No | F33: No | G33: No major surgery | H33: yes | I33: =IF(LOWER(TRIM(D33))="yes","Yes","No") -> Yes | J33: =IF(LOWER(TRIM(E33))="yes","Yes","No") -> No | K33: =IF(LOWER(TRIM(F33))="yes","Yes","No") -> No | L33: =IF(TRIM(H33)="?",'Cleaning Summary'!$B$35,IF(LOWER(TRIM(H33))="yes","Yes","No")) -> Yes | M33: =IF(ISNUMBER(G33),G33,IF(LOWER(TRIM(G33))="no major surgery",0,"CHECK")) -> 0 | N33: =IF(B33<'Cleaning Summary'!$B$63,"Underweight",IF(B33<'Cleaning Summary'!$B$64,"Normal Weight",IF(B33<'Cleaning Summary'!$B$65,"Overweight","Obesity"))) -> Obesity | O33: =IF(C33<'Cleaning Summary'!$B$66,"Normal",IF(C33<'Cleaning Summary'!$B$67,"Prediabetes","Diabetes")) -> Normal
A34: Id33 | B34: 31.35 | C34: 6.86 | D34: No | E34: No | F34: No | G34: No major surgery | H34: yes | I34: =IF(LOWER(TRIM(D34))="yes","Yes","No") -> No | J34: =IF(LOWER(TRIM(E34))="yes","Yes","No") -> No | K34: =IF(LOWER(TRIM(F34))="yes","Yes","No") -> No | L34: =IF(TRIM(H34)="?",'Cleaning Summary'!$B$35,IF(LOWER(TRIM(H34))="yes","Yes","No")) -> Yes | M34: =IF(ISNUMBER(G34),G34,IF(LOWER(TRIM(G34))="no major surgery",0,"CHECK")) -> 0 | N34: =IF(B34<'Cleaning Summary'!$B$63,"Underweight",IF(B34<'Cleaning Summary'!$B$64,"Normal Weight",IF(B34<'Cleaning Summary'!$B$65,"Overweight","Obesity"))) -> Obesity | O34: =IF(C34<'Cleaning Summary'!$B$66,"Normal",IF(C34<'Cleaning Summary'!$B$67,"Prediabetes","Diabetes")) -> Diabetes
A35: Id34 | B35: 47.6 | C35: 5.95 | D35: yes | E35: No | F35: No | G35: No major surgery | H35: yes | I35: =IF(LOWER(TRIM(D35))="yes","Yes","No") -> Yes | J35: =IF(LOWER(TRIM(E35))="yes","Yes","No") -> No | K35: =IF(LOWER(TRIM(F35))="yes","Yes","No") -> No | L35: =IF(TRIM(H35)="?",'Cleaning Summary'!$B$35,IF(LOWER(TRIM(H35))="yes","Yes","No")) -> Yes | M35: =IF(ISNUMBER(G35),G35,IF(LOWER(TRIM(G35))="no major surgery",0,"CHECK")) -> 0 | N35: =IF(B35<'Cleaning Summary'!$B$63,"Underweight",IF(B35<'Cleaning Summary'!$B$64,"Normal Weight",IF(B35<'Cleaning Summary'!$B$65,"Overweight","Obesity"))) -> Obesity | O35: =IF(C35<'Cleaning Summary'!$B$66,"Normal",IF(C35<'Cleaning Summary'!$B$67,"Prediabetes","Diabetes")) -> Prediabetes
A36: Id35 | B36: 46.2 | C36: 6.09 | D36: No | E36: No | F36: Yes | G36: 1 | H36: yes | I36: =IF(LOWER(TRIM(D36))="yes","Yes","No") -> No | J36: =IF(LOWER(TRIM(E36))="yes","Yes","No") -> No | K36: =IF(LOWER(TRIM(F36))="yes","Yes","No") -> Yes | L36: =IF(TRIM(H36)="?",'Cleaning Summary'!$B$35,IF(LOWER(TRIM(H36))="yes","Yes","No")) -> Yes | M36: =IF(ISNUMBER(G36),G36,IF(LOWER(TRIM(G36))="no major surgery",0,"CHECK")) -> 1 | N36: =IF(B36<'Cleaning Summary'!$B$63,"Underweight",IF(B36<'Cleaning Summary'!$B$64,"Normal Weight",IF(B36<'Cleaning Summary'!$B$65,"Overweight","Obesity"))) -> Obesity | O36: =IF(C36<'Cleaning Summary'!$B$66,"Normal",IF(C36<'Cleaning Summary'!$B$67,"Prediabetes","Diabetes")) -> Prediabetes
A37: Id36 | B37: 32.015 | C37: 11.75 | D37: No | E37: No | F37: No | G37: No major surgery | H37: yes | I37: =IF(LOWER(TRIM(D37))="yes","Yes","No") -> No | J37: =IF(LOWER(TRIM(E37))="yes","Yes","No") -> No | K37: =IF(LOWER(TRIM(F37))="yes","Yes","No") -> No | L37: =IF(TRIM(H37)="?",'Cleaning Summary'!$B$35,IF(LOWER(TRIM(H37))="yes","Yes","No")) -> Yes | M37: =IF(ISNUMBER(G37),G37,IF(LOWER(TRIM(G37))="no major surgery",0,"CHECK")) -> 0 | N37: =IF(B37<'Cleaning Summary'!$B$63,"Underweight",IF(B37<'Cleaning Summary'!$B$64,"Normal Weight",IF(B37<'Cleaning Summary'!$B$65,"Overweight","Obesity"))) -> Obesity | O37: =IF(C37<'Cleaning Summary'!$B$66,"Normal",IF(C37<'Cleaning Summary'!$B$67,"Prediabetes","Diabetes")) -> Diabetes
A38: Id37 | B38: 40.565 | C38: 7.37 | D38: No | E38: No | F38: No | G38: No major surgery | H38: yes | I38: =IF(LOWER(TRIM(D38))="yes","Yes","No") -> No | J38: =IF(LOWER(TRIM(E38))="yes","Yes","No") -> No | K38: =IF(LOWER(TRIM(F38))="yes","Yes","No") -> No | L38: =IF(TRIM(H38)="?",'Cleaning Summary'!$B$35,IF(LOWER(TRIM(H38))="yes","Yes","No")) -> Yes | M38: =IF(ISNUMBER(G38),G38,IF(LOWER(TRIM(G38))="no major surgery",0,"CHECK")) -> 0 | N38: =IF(B38<'Cleaning Summary'!$B$63,"Underweight",IF(B38<'Cleaning Summary'!$B$64,"Normal Weight",IF(B38<'Cleaning Summary'!$B$65,"Overweight","Obesity"))) -> Obesity | O38: =IF(C38<'Cleaning Summary'!$B$66,"Normal",IF(C38<'Cleaning Summary'!$B$67,"Prediabetes","Diabetes")) -> Diabetes
A39: Id38 | B39: 32.45 | C39: 11.91 | D39: No | E39: No | F39: No | G39: No major surgery | H39: yes | I39: =IF(LOWER(TRIM(D39))="yes","Yes","No") -> No | J39: =IF(LOWER(TRIM(E39))="yes","Yes","No") -> No | K39: =IF(LOWER(TRIM(F39))="yes","Yes","No") -> No | L39: =IF(TRIM(H39)="?",'Cleaning Summary'!$B$35,IF(LOWER(TRIM(H39))="yes","Yes","No")) -> Yes | M39: =IF(ISNUMBER(G39),G39,IF(LOWER(TRIM(G39))="no major surgery",0,"CHECK")) -> 0 | N39: =IF(B39<'Cleaning Summary'!$B$63,"Underweight",IF(B39<'Cleaning Summary'!$B$64,"Normal Weight",IF(B39<'Cleaning Summary'!$B$65,"Overweight","Obesity"))) -> Obesity | O39: =IF(C39<'Cleaning Summary'!$B$66,"Normal",IF(C39<'Cleaning Summary'!$B$67,"Prediabetes","Diabetes")) -> Diabetes
A40: Id39 | B40: 34.96 | C40: 6.52 | D40: No | E40: No | F40: No | G40: No major surgery | H40: yes | I40: =IF(LOWER(TRIM(D40))="yes","Yes","No") -> No | J40: =IF(LOWER(TRIM(E40))="yes","Yes","No") -> No | K40: =IF(LOWER(TRIM(F40))="yes","Yes","No") -> No | L40: =IF(TRIM(H40)="?",'Cleaning Summary'!$B$35,IF(LOWER(TRIM(H40))="yes","Yes","No")) -> Yes | M40: =IF(ISNUMBER(G40),G40,IF(LOWER(TRIM(G40))="no major surgery",0,"CHECK")) -> 0 | N40: =IF(B40<'Cleaning Summary'!$B$63,"Underweight",IF(B40<'Cleaning Summary'!$B$64,"Normal Weight",IF(B40<'Cleaning Summary'!$B$65,"Overweight","Obesity"))) -> Obesity | O40: =IF(C40<'Cleaning Summary'!$B$66,"Normal",IF(C40<'Cleaning Summary'!$B$67,"Prediabetes","Diabetes")) -> Diabetes
...

Sheet Hospitalisation Details
A1: Customer ID | B1: year | C1: month | D1: date | E1: children | F1: charges | G1: Hospital tier | H1: City tier | I1: State ID | J1: year (clean) | K1: month (clean) | L1: Hospital tier (clean) | M1: City tier (clean) | N1: State ID (clean) | O1: Date of Birth | P1: Age
A2: Id2335 | B2: 1992 | C2: Jul | D2: 9 | E2: 0 | F2: 563.84 | G2: tier - 2 | H2: tier - 3 | I2: R1013 | J2: =IF(TRIM(B2)="?",'Cleaning Summary'!$B$28,B2) -> 1992 | K2: =IF(TRIM(C2)="?",'Cleaning Summary'!$B$27,C2) -> Jul | L2: =IF(TRIM(G2)="?",'Cleaning Summary'!$B$40,G2) -> tier - 2 | M2: =IF(TRIM(H2)="?",'Cleaning Summary'!$B$45,H2) -> tier - 3 | N2: =IF(TRIM(I2)="?",'Cleaning Summary'!$B$29,I2) -> R1013 | O2: =DATE(J2,MATCH(K2,{"Jan","Feb","Mar","Apr","May","Jun","Jul","Aug","Sep","Oct","Nov","Dec"},0),D2) -> 33794 | P2: =DATEDIF(O2,'Cleaning Summary'!$B$62,"Y") -> 30
A3: Id2334 | B3: 1992 | C3: Nov | D3: 30 | E3: 0 | F3: 570.62 | G3: tier - 2 | H3: tier - 1 | I3: R1013 | J3: =IF(TRIM(B3)="?",'Cleaning Summary'!$B$28,B3) -> 1992 | K3: =IF(TRIM(C3)="?",'Cleaning Summary'!$B$27,C3) -> Nov | L3: =IF(TRIM(G3)="?",'Cleaning Summary'!$B$40,G3) -> tier - 2 | M3: =IF(TRIM(H3)="?",'Cleaning Summary'!$B$45,H3) -> tier - 1 | N3: =IF(TRIM(I3)="?",'Cleaning Summary'!$B$29,I3) -> R1013 | O3: =DATE(J3,MATCH(K3,{"Jan","Feb","Mar","Apr","May","Jun","Jul","Aug","Sep","Oct","Nov","Dec"},0),D3) -> 33938 | P3: =DATEDIF(O3,'Cleaning Summary'!$B$62,"Y") -> 30
A4: Id2333 | B4: 1993 | C4: Jun | D4: 30 | E4: 0 | F4: 600 | G4: tier - 2 | H4: tier - 1 | I4: R1013 | J4: =IF(TRIM(B4)="?",'Cleaning Summary'!$B$28,B4) -> 1993 | K4: =IF(TRIM(C4)="?",'Cleaning Summary'!$B$27,C4) -> Jun | L4: =IF(TRIM(G4)="?",'Cleaning Summary'!$B$40,G4) -> tier - 2 | M4: =IF(TRIM(H4)="?",'Cleaning Summary'!$B$45,H4) -> tier - 1 | N4: =IF(TRIM(I4)="?",'Cleaning Summary'!$B$29,I4) -> R1013 | O4: =DATE(J4,MATCH(K4,{"Jan","Feb","Mar","Apr","May","Jun","Jul","Aug","Sep","Oct","Nov","Dec"},0),D4) -> 34150 | P4: =DATEDIF(O4,'Cleaning Summary'!$B$62,"Y") -> 29
A5: Id2332 | B5: 1992 | C5: Sep | D5: 13 | E5: 0 | F5: 604.54 | G5: tier - 3 | H5: tier - 3 | I5: R1013 | J5: =IF(TRIM(B5)="?",'Cleaning Summary'!$B$28,B5) -> 1992 | K5: =IF(TRIM(C5)="?",'Cleaning Summary'!$B$27,C5) -> Sep | L5: =IF(TRIM(G5)="?",'Cleaning Summary'!$B$40,G5) -> tier - 3 | M5: =IF(TRIM(H5)="?",'Cleaning Summary'!$B$45,H5) -> tier - 3 | N5: =IF(TRIM(I5)="?",'Cleaning Summary'!$B$29,I5) -> R1013 | O5: =DATE(J5,MATCH(K5,{"Jan","Feb","Mar","Apr","May","Jun","Jul","Aug","Sep","Oct","Nov","Dec"},0),D5) -> 33860 | P5: =DATEDIF(O5,'Cleaning Summary'!$B$62,"Y") -> 30
A6: Id2331 | B6: 1998 | C6: Jul | D6: 27 | E6: 0 | F6: 637.26 | G6: tier - 3 | H6: tier - 3 | I6: R1013 | J6: =IF(TRIM(B6)="?",'Cleaning Summary'!$B$28,B6) -> 1998 | K6: =IF(TRIM(C6)="?",'Cleaning Summary'!$B$27,C6) -> Jul | L6: =IF(TRIM(G6)="?",'Cleaning Summary'!$B$40,G6) -> tier - 3 | M6: =IF(TRIM(H6)="?",'Cleaning Summary'!$B$45,H6) -> tier - 3 | N6: =IF(TRIM(I6)="?",'Cleaning Summary'!$B$29,I6) -> R1013 | O6: =DATE(J6,MATCH(K6,{"Jan","Feb","Mar","Apr","May","Jun","Jul","Aug","Sep","Oct","Nov","Dec"},0),D6) -> 36003 | P6: =DATEDIF(O6,'Cleaning Summary'!$B$62,"Y") -> 24
A7: Id2330 | B7: 2001 | C7: Nov | D7: 20 | E7: 0 | F7: 646.14 | G7: tier - 3 | H7: tier - 3 | I7: R1012 | J7: =IF(TRIM(B7)="?",'Cleaning Summary'!$B$28,B7) -> 2001 | K7: =IF(TRIM(C7)="?",'Cleaning Summary'!$B$27,C7) -> Nov | L7: =IF(TRIM(G7)="?",'Cleaning Summary'!$B$40,G7) -> tier - 3 | M7: =IF(TRIM(H7)="?",'Cleaning Summary'!$B$45,H7) -> tier - 3 | N7: =IF(TRIM(I7)="?",'Cleaning Summary'!$B$29,I7) -> R1012 | O7: =DATE(J7,MATCH(K7,{"Jan","Feb","Mar","Apr","May","Jun","Jul","Aug","Sep","Oct","Nov","Dec"},0),D7) -> 37215 | P7: =DATEDIF(O7,'Cleaning Summary'!$B$62,"Y") -> 21
A8: Id2329 | B8: 1993 | C8: Jun | D8: 1 | E8: 0 | F8: 650 | G8: tier - 3 | H8: tier - 3 | I8: R1013 | J8: =IF(TRIM(B8)="?",'Cleaning Summary'!$B$28,B8) -> 1993 | K8: =IF(TRIM(C8)="?",'Cleaning Summary'!$B$27,C8) -> Jun | L8: =IF(TRIM(G8)="?",'Cleaning Summary'!$B$40,G8) -> tier - 3 | M8: =IF(TRIM(H8)="?",'Cleaning Summary'!$B$45,H8) -> tier - 3 | N8: =IF(TRIM(I8)="?",'Cleaning Summary'!$B$29,I8) -> R1013 | O8: =DATE(J8,MATCH(K8,{"Jan","Feb","Mar","Apr","May","Jun","Jul","Aug","Sep","Oct","Nov","Dec"},0),D8) -> 34121 | P8: =DATEDIF(O8,'Cleaning Summary'!$B$62,"Y") -> 30
A9: Id2328 | B9: 1995 | C9: Jul | D9: 4 | E9: 0 | F9: 650 | G9: tier - 3 | H9: tier - 3 | I9: R1013 | J9: =IF(TRIM(B9)="?",'Cleaning Summary'!$B$28,B9) -> 1995 | K9: =IF(TRIM(C9)="?",'Cleaning Summary'!$B$27,C9) -> Jul | L9: =IF(TRIM(G9)="?",'Cleaning Summary'!$B$40,G9) -> tier - 3 | M9: =IF(TRIM(H9)="?",'Cleaning Summary'!$B$45,H9) -> tier - 3 | N9: =IF(TRIM(I9)="?",'Cleaning Summary'!$B$29,I9) -> R1013 | O9: =DATE(J9,MATCH(K9,{"Jan","Feb","Mar","Apr","May","Jun","Jul","Aug","Sep","Oct","Nov","Dec"},0),D9) -> 34884 | P9: =DATEDIF(O9,'Cleaning Summary'!$B$62,"Y") -> 27
A10: Id2327 | B10: 2002 | C10: Nov | D10: 29 | E10: 0 | F10: 668 | G10: tier - 3 | H10: tier - 2 | I10: R1012 | J10: =IF(TRIM(B10)="?",'Cleaning Summary'!$B$28,B10) -> 2002 | K10: =IF(TRIM(C10)="?",'Cleaning Summary'!$B$27,C10) -> Nov | L10: =IF(TRIM(G10)="?",'Cleaning Summary'!$B$40,G10) -> tier - 3 | M10: =IF(TRIM(H10)="?",'Cleaning Summary'!$B$45,H10) -> tier - 2 | N10: =IF(TRIM(I10)="?",'Cleaning Summary'!$B$29,I10) -> R1012 | O10: =DATE(J10,MATCH(K10,{"Jan","Feb","Mar","Apr","May","Jun","Jul","Aug","Sep","Oct","Nov","Dec"},0),D10) -> 37589 | P10: =DATEDIF(O10,'Cleaning Summary'!$B$62,"Y") -> 20
A11: Id2326 | B11: 1997 | C11: Nov | D11: 9 | E11: 0 | F11: 670 | G11: tier - 3 | H11: tier - 3 | I11: R1013 | J11: =IF(TRIM(B11)="?",'Cleaning Summary'!$B$28,B11) -> 1997 | K11: =IF(TRIM(C11)="?",'Cleaning Summary'!$B$27,C11) -> Nov | L11: =IF(TRIM(G11)="?",'Cleaning Summary'!$B$40,G11) -> tier - 3 | M11: =IF(TRIM(H11)="?",'Cleaning Summary'!$B$45,H11) -> tier - 3 | N11: =IF(TRIM(I11)="?",'Cleaning Summary'!$B$29,I11) -> R1013 | O11: =DATE(J11,MATCH(K11,{"Jan","Feb","Mar","Apr","May","Jun","Jul","Aug","Sep","Oct","Nov","Dec"},0),D11) -> 35743 | P11: =DATEDIF(O11,'Cleaning Summary'!$B$62,"Y") -> 25
A12: Id2325 | B12: 2001 | C12: Sep | D12: 12 | E12: 0 | F12: 687.54 | G12: tier - 3 | H12: tier - 2 | I12: R1013 | J12: =IF(TRIM(B12)="?",'Cleaning Summary'!$B$28,B12) -> 2001 | K12: =IF(TRIM(C12)="?",'Cleaning Summary'!$B$27,C12) -> Sep | L12: =IF(TRIM(G12)="?",'Cleaning Summary'!$B$40,G12) -> tier - 3 | M12: =IF(TRIM(H12)="?",'Cleaning Summary'!$B$45,H12) -> tier - 2 | N12: =IF(TRIM(I12)="?",'Cleaning Summary'!$B$29,I12) -> R1013 | O12: =DATE(J12,MATCH(K12,{"Jan","Feb","Mar","Apr","May","Jun","Jul","Aug","Sep","Oct","Nov","Dec"},0),D12) -> 37146 | P12: =DATEDIF(O12,'Cleaning Summary'!$B$62,"Y") -> 21
A13: Id2324 | B13: 1999 | C13: Dec | D13: 26 | E13: 0 | F13: 700 | G13: ? | H13: tier - 3 | I13: R1013 | J13: =IF(TRIM(B13)="?",'Cleaning Summary'!$B$28,B13) -> 1999 | K13: =IF(TRIM(C13)="?",'Cleaning Summary'!$B$27,C13) -> Dec | L13: =IF(TRIM(G13)="?",'Cleaning Summary'!$B$40,G13) -> tier - 2 | M13: =IF(TRIM(H13)="?",'Cleaning Summary'!$B$45,H13) -> tier - 3 | N13: =IF(TRIM(I13)="?",'Cleaning Summary'!$B$29,I13) -> R1013 | O13: =DATE(J13,MATCH(K13,{"Jan","Feb","Mar","Apr","May","Jun","Jul","Aug","Sep","Oct","Nov","Dec"},0),D13) -> 36520 | P13: =DATEDIF(O13,'Cleaning Summary'!$B$62,"Y") -> 23
... A1050: Id1290 | B1050: 1977 | C1050: Jul | D1050: 26 | E1050: 2 | F1050: 8527.53 | G1050: tier - 2 | H1050: tier - 2 | I1050: R1013 | J1050: =IF(TRIM(B1050)="?",'Cleaning Summary'!$B$28,B1050) -> 1977 | K1050: =IF(TRIM(C1050)="?",'Cleaning Summary'!$B$27,C1050) -> Jul | L1050: =IF(TRIM(G1050)="?",'Cleaning Summary'!$B$40,G1050) -> tier - 2 | M1050: =IF(TRIM(H1050)="?",'Cleaning Summary'!$B$45,H1050) -> tier - 2 | N1050: =IF(TRIM(I1050)="?",'Cleaning Summary'!$B$29,I1050) -> R1013 | O1050: =DATE(J1050,MATCH(K1050,{"Jan","Feb","Mar","Apr","May","Jun","Jul","Aug","Sep","Oct","Nov","Dec"},0),D1050) -> 28332 | P1050: =DATEDIF(O1050,'Cleaning Summary'!$B$62,"Y") -> 45
A1051: Id1289 | B1051: ? | C1051: Jul | D1051: 24 | E1051: 0 | F1051: 8534.67 | G1051: tier - 2 | H1051: tier - 3 | I1051: R1024 | J1051: =IF(TRIM(B1051)="?",'Cleaning Summary'!$B$28,B1051) -> 1983 | K1051: =IF(TRIM(C1051)="?",'Cleaning Summary'!$B$27,C1051) -> Jul | L1051: =IF(TRIM(G1051)="?",'Cleaning Summary'!$B$40,G1051) -> tier - 2 | M1051: =IF(TRIM(H1051)="?",'Cleaning Summary'!$B$45,H1051) -> tier - 3 | N1051: =IF(TRIM(I1051)="?",'Cleaning Summary'!$B$29,I1051) -> R1024 | O1051: =DATE(J1051,MATCH(K1051,{"Jan","Feb","Mar","Apr","May","Jun","Jul","Aug","Sep","Oct","Nov","Dec"},0),D1051) -> 30521 | P1051: =DATEDIF(O1051,'Cleaning Summary'!$B$62,"Y") -> 39
A1052: Id1288 | B1052: 1981 | C1052: Dec | D1052: 27 | E1052: 3 | F1052: 8538.29 | G1052: tier - 2 | H1052: tier - 3 | I1052: R1024 | J1052: =IF(TRIM(B1052)="?",'Cleaning Summary'!$B$28,B1052) -> 1981 | K1052: =IF(TRIM(C1052)="?",'Cleaning Summary'!$B$27,C1052) -> Dec | L1052: =IF(TRIM(G1052)="?",'Cleaning Summary'!$B$40,G1052) -> tier - 2 | M1052: =IF(TRIM(H1052)="?",'Cleaning Summary'!$B$45,H1052) -> tier - 3 | N1052: =IF(TRIM(I1052)="?",'Cleaning Summary'!$B$29,I1052) -> R1024 | O1052: =DATE(J1052,MATCH(K1052,{"Jan","Feb","Mar","Apr","May","Jun","Jul","Aug","Sep","Oct","Nov","Dec"},0),D1052) -> 29947 | P1052: =DATEDIF(O1052,'Cleaning Summary'!$B$62,"Y") -> 41
A1053: Id1287 | B1053: 1975 | C1053: Nov | D1053: 6 | E1053: 1 | F1053: 8539.67 | G1053: tier - 2 | H1053: tier - 3 | I1053: R1011 | J1053: =IF(TRIM(B1053)="?",'Cleaning Summary'!$B$28,B1053) -> 1975 | K1053: =IF(TRIM(C1053)="?",'Cleaning Summary'!$B$27,C1053) -> Nov | L1053: =IF(TRIM(G1053)="?",'Cleaning Summary'!$B$40,G1053) -> tier - 2 | M1053: =IF(TRIM(H1053)="?",'Cleaning Summary'!$B$45,H1053) -> tier - 3 | N1053: =IF(TRIM(I1053)="?",'Cleaning Summary'!$B$29,I1053) -> R1011 | O1053: =DATE(J1053,MATCH(K1053,{"Jan","Feb","Mar","Apr","May","Jun","Jul","Aug","Sep","Oct","Nov","Dec"},0),D1053) -> 27704 | P1053: =DATEDIF(O1053,'Cleaning Summary'!$B$62,"Y") -> 47
A1054: Id1286 | B1054: ? | C1054: Dec | D1054: 12 | E1054: 1 | F1054: 8547.69 | G1054: tier - 2 | H1054: tier - 1 | I1054: R1013 | J1054: =IF(TRIM(B1054)="?",'Cleaning Summary'!$B$28,B1054) -> 1983 | K1054: =IF(TRIM(C1054)="?",'Cleaning Summary'!$B$27,C1054) -> Dec | L1054: =IF(TRIM(G1054)="?",'Cleaning Summary'!$B$40,G1054) -> tier - 2 | M1054: =IF(TRIM(H1054)="?",'Cleaning Summary'!$B$45,H1054) -> tier - 1 | N1054: =IF(TRIM(I1054)="?",'Cleaning Summary'!$B$29,I1054) -> R1013 | O1054: =DATE(J1054,MATCH(K1054,{"Jan","Feb","Mar","Apr","May","Jun","Jul","Aug","Sep","Oct","Nov","Dec"},0),D1054) -> 30662 | P1054: =DATEDIF(O1054,'Cleaning Summary'!$B$62,"Y") -> 39
A1055: Id1285 | B1055: 1975 | C1055: Aug | D1055: 6 | E1055: 1 | F1055: 8551.35 | G1055: tier - 2 | H1055: tier - 2 | I1055: R1011 | J1055: =IF(TRIM(B1055)="?",'Cleaning Summary'!$B$28,B1055) -> 1975 | K1055: =IF(TRIM(C1055)="?",'Cleaning Summary'!$B$27,C1055) -> Aug | L1055: =IF(TRIM(G1055)="?",'Cleaning Summary'!$B$40,G1055) -> tier - 2 | M1055: =IF(TRIM(H1055)="?",'Cleaning Summary'!$B$45,H1055) -> tier - 2 | N1055: =IF(TRIM(I1055)="?",'Cleaning Summary'!$B$29,I1055) -> R1011 | O1055: =DATE(J1055,MATCH(K1055,{"Jan","Feb","Mar","Apr","May","Jun","Jul","Aug","Sep","Oct","Nov","Dec"},0),D1055) -> 27612 | P1055: =DATEDIF(O1055,'Cleaning Summary'!$B$62,"Y") -> 47
A1056: Id1284 | B1056: 1975 | C1056: Aug | D1056: 21 | E1056: 1 | F1056: 8556.91 | G1056: tier - 2 | H1056: tier - 1 | I1056: R1011 | J1056: =IF(TRIM(B1056)="?",'Cleaning Summary'!$B$28,B1056) -> 1975 | K1056: =IF(TRIM(C1056)="?",'Cleaning Summary'!$B$27,C1056) -> Aug | L1056: =IF(TRIM(G1056)="?",'Cleaning Summary'!$B$40,G1056) -> tier - 2 | M1056: =IF(TRIM(H1056)="?",'Cleaning Summary'!$B$45,H1056) -> tier - 1 | N1056: =IF(TRIM(I1056)="?",'Cleaning Summary'!$B$29,I1056) -> R1011 | O1056: =DATE(J1056,MATCH(K1056,{"Jan","Feb","Mar","Apr","May","Jun","Jul","Aug","Sep","Oct","Nov","Dec"},0),D1056) -> 27627 | P1056: =DATEDIF(O1056,'Cleaning Summary'!$B$62,"Y") -> 47
A1057: Id1283 | B1057: 1988 | C1057: Sep | D1057: 21 | E1057: 3 | F1057: 8567.25 | G1057: tier - 2 | H1057: tier - 1 | I1057: R1012 | J1057: =IF(TRIM(B1057)="?",'Cleaning Summary'!$B$28,B1057) -> 1988 | K1057: =IF(TRIM(C1057)="?",'Cleaning Summary'!$B$27,C1057) -> Sep | L1057: =IF(TRIM(G1057)="?",'Cleaning Summary'!$B$40,G1057) -> tier - 2 | M1057: =IF(TRIM(H1057)="?",'Cleaning Summary'!$B$45,H1057) -> tier - 1 | N1057: =IF(TRIM(I1057)="?",'Cleaning Summary'!$B$29,I1057) -> R1012 | O1057: =DATE(J1057,MATCH(K1057,{"Jan","Feb","Mar","Apr","May","Jun","Jul","Aug","Sep","Oct","Nov","Dec"},0),D1057) -> 32407 | P1057: =DATEDIF(O1057,'Cleaning Summary'!$B$62,"Y") -> 34
A1058: Id1282 | B1058: 1975 | C1058: Sep | D1058: 26 | E1058: 1 | F1058: 8569.86 | G1058: tier - 2 | H1058: tier - 3 | I1058: R1013 | J1058: =IF(TRIM(B1058)="?",'Cleaning Summary'!$B$28,B1058) -> 1975 | K1058: =IF(TRIM(C1058)="?",'Cleaning Summary'!$B$27,C1058) -> Sep | L1058: =IF(TRIM(G1058)="?",'Cleaning Summary'!$B$40,G1058) -> tier - 2 | M1058: =IF(TRIM(H1058)="?",'Cleaning Summary'!$B$45,H1058) -> tier - 3 | N1058: =IF(TRIM(I1058)="?",'Cleaning Summary'!$B$29,I1058) -> R1013 | O1058: =DATE(J1058,MATCH(K1058,{"Jan","Feb","Mar","Apr","May","Jun","Jul","Aug","Sep","Oct","Nov","Dec"},0),D1058) -> 27663 | P1058: =DATEDIF(O1058,'Cleaning Summary'!$B$62,"Y") -> 47
A1059: Id1281 | B1059: 1982 | C1059: Dec | D1059: 6 | E1059: 3 | F1059: 8572.04 | G1059: tier - 2 | H1059: tier - 2 | I1059: R1021 | J1059: =IF(TRIM(B1059)="?",'Cleaning Summary'!$B$28,B1059) -> 1982 | K1059: =IF(TRIM(C1059)="?",'Cleaning Summary'!$B$27,C1059) -> Dec | L1059: =IF(TRIM(G1059)="?",'Cleaning Summary'!$B$40,G1059) -> tier - 2 | M1059: =IF(TRIM(H1059)="?",'Cleaning Summary'!$B$45,H1059) -> tier - 2 | N1059: =IF(TRIM(I1059)="?",'Cleaning Summary'!$B$29,I1059) -> R1021 | O1059: =DATE(J1059,MATCH(K1059,{"Jan","Feb","Mar","Apr","May","Jun","Jul","Aug","Sep","Oct","Nov","Dec"},0),D1059) -> 30291 | P1059: =DATEDIF(O1059,'Cleaning Summary'!$B$62,"Y") -> 40
A1060: Id1280 | B1060: 1987 | C1060: Nov | D1060: 11 | E1060: 3 | F1060: 8573.3 | G1060: tier - 2 | H1060: tier - 2 | I1060: R1021 | J1060: =IF(TRIM(B1060)="?",'Cleaning Summary'!$B$28,B1060) -> 1987 | K1060: =IF(TRIM(C1060)="?",'Cleaning Summary'!$B$27,C1060) -> Nov | L1060: =IF(TRIM(G1060)="?",'Cleaning Summary'!$B$40,G1060) -> tier - 2 | M1060: =IF(TRIM(H1060)="?",'Cleaning Summary'!$B$45,H1060) -> tier - 2 | N1060: =IF(TRIM(I1060)="?",'Cleaning Summary'!$B$29,I1060) -> R1021 | O1060: =DATE(J1060,MATCH(K1060,{"Jan","Feb","Mar","Apr","May","Jun","Jul","Aug","Sep","Oct","Nov","Dec"},0),D1060) -> 32092 | P1060: =DATEDIF(O1060,'Cleaning Summary'!$B$62,"Y") -> 35
A1061: Id1279 | B1061: 1983 | C1061: Dec | D1061: 30 | E1061: 5 | F1061: 8582.3 | G1061: tier - 2 | H1061: tier - 1 | I1061: R1013 | J1061: =IF(TRIM(B1061)="?",'Cleaning Summary'!$B$28,B1061) -> 1983 | K1061: =IF(TRIM(C1061)="?",'Cleaning Summary'!$B$27,C1061) -> Dec | L1061: =IF(TRIM(G1061)="?",'Cleaning Summary'!$B$40,G1061) -> tier - 2 | M1061: =IF(TRIM(H1061)="?",'Cleaning Summary'!$B$45,H1061) -> tier - 1 | N1061: =IF(TRIM(I1061)="?",'Cleaning Summary'!$B$29,I1061) -> R1013 | O1061: =DATE(J1061,MATCH(K1061,{"Jan","Feb","Mar","Apr","May","Jun","Jul","Aug","Sep","Oct","Nov","Dec"},0),D1061) -> 30680 | P1061: =DATEDIF(O1061,'Cleaning Summary'!$B$62,"Y") -> 39
A1062: Id1278 | B1062: 1983 | C1062: Jul | D1062: 25 | E1062: 5 | F1062: 8596.83 | G1062: tier - 2 | H1062: tier - 3 | I1062: R1013 | J1062: =IF(TRIM(B1062)="?",'Cleaning Summary'!$B$28,B1062) -> 1983 | K1062: =IF(TRIM(C1062)="?",'Cleaning Summary'!$B$27,C1062) -> Jul | L1062: =IF(TRIM(G1062)="?",'Cleaning Summary'!$B$40,G1062) -> tier - 2 | M1062: =IF(TRIM(H1062)="?",'Cleaning Summary'!$B$45,H1062) -> tier - 3 | N1062: =IF(TRIM(I1062)="?",'Cleaning Summary'!$B$29,I1062) -> R1013 | O1062: =DATE(J1062,MATCH(K1062,{"Jan","Feb","Mar","Apr","May","Jun","Jul","Aug","Sep","Oct","Nov","Dec"},0),D1062) -> 30522 | P1062: =DATEDIF(O1062,'Cleaning Summary'!$B$62,"Y") -> 39
A1063: Id1277 | B1063: 1973 | C1063: Jul | D1063: 11 | E1063: 0 | F1063: 8601.33 | G1063: tier - 2 | H1063: tier - 1 | I1063: R1013 | J1063: =IF(TRIM(B1063)="?",'Cleaning Summary'!$B$28,B1063) -> 1973 | K1063: =IF(TRIM(C1063)="?",'Cleaning Summary'!$B$27,C1063) -> Jul | L1063: =IF(TRIM(G1063)="?",'Cleaning Summary'!$B$40,G1063) -> tier - 2 | M1063: =IF(TRIM(H1063)="?",'Cleaning Summary'!$B$45,H1063) -> tier - 1 | N1063: =IF(TRIM(I1063)="?",'Cleaning Summary'!$B$29,I1063) -> R1013 | O1063: =DATE(J1063,MATCH(K1063,{"Jan","Feb","Mar","Apr","May","Jun","Jul","Aug","Sep","Oct","Nov","Dec"},0),D1063) -> 26856 | P1063: =DATEDIF(O1063,'Cleaning Summary'!$B$62,"Y") -> 49
A1064: Id1276 | B1064: 1977 | C1064: Sep | D1064: 24 | E1064: 2 | F1064: 8603.82 | G1064: tier - 2 | H1064: tier - 1 | I1064: R1019 | J1064: =IF(TRIM(B1064)="?",'Cleaning Summary'!$B$28,B1064) -> 1977 | K1064: =IF(TRIM(C1064)="?",'Cleaning Summary'!$B$27,C1064) -> Sep | L1064: =IF(TRIM(G1064)="?",'Cleaning Summary'!$B$40,G1064) -> tier - 2 | M1064: =IF(TRIM(H1064)="?",'Cleaning Summary'!$B$45,H1064) -> tier - 1 | N1064: =IF(TRIM(I1064)="?",'Cleaning Summary'!$B$29,I1064) -> R1019 | O1064: =DATE(J1064,MATCH(K1064,{"Jan","Feb","Mar","Apr","May","Jun","Jul","Aug","Sep","Oct","Nov","Dec"},0),D1064) -> 28392 | P1064: =DATEDIF(O1064,'Cleaning Summary'!$B$62,"Y") -> 45
A1065: Id1275 | B1065: 1977 | C1065: Nov | D1065: 12 | E1065: 2 | F1065: 8604.48 | G1065: tier - 3 | H1065: tier - 2 | I1065: R1016 | J1065: =IF(TRIM(B1065)="?",'Cleaning Summary'!$B$28,B1065) -> 1977 | K1065: =IF(TRIM(C1065)="?",'Cleaning Summary'!$B$27,C1065) -> Nov | L1065: =IF(TRIM(G1065)="?",'Cleaning Summary'!$B$40,G1065) -> tier - 3 | M1065: =IF(TRIM(H1065)="?",'Cleaning Summary'!$B$45,H1065) -> tier - 2 | N1065: =IF(TRIM(I1065)="?",'Cleaning Summary'!$B$29,I1065) -> R1016 | O1065: =DATE(J1065,MATCH(K1065,{"Jan","Feb","Mar","Apr","May","Jun","Jul","Aug","Sep","Oct","Nov","Dec"},0),D1065) -> 28441 | P1065: =DATEDIF(O1065,'Cleaning Summary'!$B$62,"Y") -> 45
A1066: Id1274 | B1066: 1977 | C1066: Oct | D1066: 15 | E1066: 3 | F1066: 8605.36 | G1066: tier - 2 | H1066: tier - 2 | I1066: R1013 | J1066: =IF(TRIM(B1066)="?",'Cleaning Summary'!$B$28,B1066) -> 1977 | K1066: =IF(TRIM(C1066)="?",'Cleaning Summary'!$B$27,C1066) -> Oct | L1066: =IF(TRIM(G1066)="?",'Cleaning Summary'!$B$40,G1066) -> tier - 2 | M1066: =IF(TRIM(H1066)="?",'Cleaning Summary'!$B$45,H1066) -> tier - 2 | N1066: =IF(TRIM(I1066)="?",'Cleaning Summary'!$B$29,I1066) -> R1013 | O1066: =DATE(J1066,MATCH(K1066,{"Jan","Feb","Mar","Apr","May","Jun","Jul","Aug","Sep","Oct","Nov","Dec"},0),D1066) -> 28413 | P1066: =DATEDIF(O1066,'Cleaning Summary'!$B$62,"Y") -> 45
... A2344: Id1 | B2344: 1968 | C2344: Oct | D2344: 12 | E2344: 0 | F2344: 63770.43 | G2344: tier - 1 | H2344: tier - 3 | I2344: R1013 | J2344: =IF(TRIM(B2344)="?",'Cleaning Summary'!$B$28,B2344) -> 1968 | K2344: =IF(TRIM(C2344)="?",'Cleaning Summary'!$B$27,C2344) -> Oct | L2344: =IF(TRIM(G2344)="?",'Cleaning Summary'!$B$40,G2344) -> tier - 1 | M2344: =IF(TRIM(H2344)="?",'Cleaning Summary'!$B$45,H2344) -> tier - 3 | N2344: =IF(TRIM(I2344)="?",'Cleaning Summary'!$B$29,I2344) -> R1013 | O2344: =DATE(J2344,MATCH(K2344,{"Jan","Feb","Mar","Apr","May","Jun","Jul","Aug","Sep","Oct","Nov","Dec"},0),D2344) -> 25123 | P2344: =DATEDIF(O2344,'Cleaning Summary'!$B$62,"Y") -> 54

Sheet Healthcare
A1: Customer ID | B1: First Name | C1: BMI | D1: HBA1C | E1: Heart Issues | F1: Any Transplants | G1: Cancer history | H1: NumberOfMajorSurgeries | I1: smoker | J1: Weight Status | K1: Diabetes Status | L1: Date of Birth | M1: charges | N1: Hospital tier | O1: City tier | P1: State ID | Q1: Age
